Workbook
Name Administrative: '[1]Cass Lake'!$K$13
Name Marketing: '[1]Cass Lake'!$K$14
Name Operations: '[1]Cass Lake'!$K$15
Name Salaries_Wages: '[1]Cass Lake'!$K$12

Sheet Instructions
A2: Excel Practice Exam 1

Sheet Project 1
A1: Blue Lake Sports
A2: First Quarter Sales by City
A3: Department | B3: Week 1 | C3: Week 2 | D3: Week 3 | E3: Week 4 | F3: Total
A4: Apparel | B4: 2600 | C4: 3200 | D4: 3800 | E4: 3700 | F4: =SUM(January_Sale[[#This Row],[Week 1]:[Week 4]]) -> 13300
A5: Baseball | B5: 3500 | C5: 1200 | D5: 1350 | E5: 2100 | F5: =SUM(January_Sale[[#This Row],[Week 1]:[Week 4]]) -> 8150
A6: Basketball | B6: 1800 | C6: 1800 | D6: 2250 | E6: 1400 | F6: =SUM(January_Sale[[#This Row],[Week 1]:[Week 4]]) -> 7250
A7: Bike & Skate | B7: 1500 | C7: 1325 | D7: 1225 | E7: 2450 | F7: =SUM(January_Sale[[#This Row],[Week 1]:[Week 4]]) -> 6500
A8: Fishing | B8: 2350 | C8: 1035 | D8: 1250 | E8: 2750 | F8: =SUM(January_Sale[[#This Row],[Week 1]:[Week 4]]) -> 7385
A9: Fitness | B9: 2650 | C9: 2875 | D9: 3250 | E9: 3775 | F9: =SUM(January_Sale[[#This Row],[Week 1]:[Week 4]]) -> 12550
A10: Footwear | B10: 1875 | C10: 2675 | D10: 3575 | E10: 3250 | F10: =SUM(January_Sale[[#This Row],[Week 1]:[Week 4]]) -> 11375
A11: Game Room | B11: 1300 | C11: 1500 | D11: 1900 | E11: 1050 | F11: =SUM(January_Sale[[#This Row],[Week 1]:[Week 4]]) -> 5750
A12: Golf | B12: 4750 | C12: 875 | D12: 925 | E12: 5400 | F12: =SUM(January_Sale[[#This Row],[Week 1]:[Week 4]]) -> 11950
A13: Hockey | B13: 850 | C13: 1875 | D13: 1950 | E13: 750 | F13: =SUM(January_Sale[[#This Row],[Week 1]:[Week 4]]) -> 5425
A14: Hunting | B14: 2000 | C14: 1000 | D14: 650 | E14: 725 | F14: =SUM(January_Sale[[#This Row],[Week 1]:[Week 4]]) -> 4375
A15: Lacrosse | B15: 1750 | C15: 1800 | D15: 1750 | E15: 1375 | F15: =SUM(January_Sale[[#This Row],[Week 1]:[Week 4]]) -> 6675
... A17: Winter Sports | B17: 1250 | C17: 34350 | D17: 2750 | E17: 550 | F17: =SUM(January_Sale[[#This Row],[Week 1]:[Week 4]]) -> 38900
A18: Total | B18: =SUBTOTAL(101,January_Sale[Week 1]) -> 2150 | C18: =SUBTOTAL(105,January_Sale[Week 2]) -> 875 | D18: =SUBTOTAL(104,January_Sale[Week 3]) -> 3800 | E18: =MEDIAN(E4:E17) -> 2275 | F18: =SUBTOTAL(109,January_Sale[Total]) -> 149360

Sheet Project 2
A1: San Diego Sailing
A2: Rental and Charter Fleet
A4: Boat ID | B4: Boat Type | C4: Length | D4: Model Year | E4: Seats | F4: Sleeps | G4: Galley with Stove | H4: Half-Day Rate | I4: Full Day Rate
A5: 1010 | B5: Catalina 270 | C5: 28'4" | D5: 2000 | E5: 8 | F5: 6 | G5: =IF(E5>8, "YES", "NO") -> NO | H5: 375 | I5: 650
A6: 1015 | B6: Catalina 270 | C6: 28'4" | D6: 2001 | E6: 8 | F6: 6 | G6: =IF(E6>8, "YES", "NO") -> NO | H6: 425 | I6: 725
A7: 1146 | B7: Hunter 33 | C7: 33'6" | D7: 2004 | E7: 10 | F7: 6 | G7: =IF(E7>8, "YES", "NO") -> YES | H7: 350 | I7: 500
A8: 1150 | B8: Capri 22 Mk II | C8: 24'8" | D8: 2005 | E8: 6 | F8: 4 | G8: =IF(E8>8, "YES", "NO") -> NO | H8: 325 | I8: 500
A9: 1152 | B9: Capri 22 Mk II | C9: 24'8" | D9: 2005 | E9: 6 | F9: 4 | G9: =IF(E9>8, "YES", "NO") -> NO | H9: 325 | I9: 500
A10: 1164 | B10: Capri 22 Mk II | C10: 24'8" | D10: 2006 | E10: 6 | F10: 4 | G10: =IF(E10>8, "YES", "NO") -> NO | H10: 325 | I10: 500
A11: 1168 | B11: Hunter 33 | C11: 33'6" | D11: 2007 | E11: 10 | F11: 6 | G11: =IF(E11>8, "YES", "NO") -> YES | H11: 425 | I11: 725
A12: 1175 | B12: Beneteau 40 | C12: 39'10" | D12: 2008 | E12: 12 | F12: 6 | G12: =IF(E12>8, "YES", "NO") -> YES | H12: 489 | I12: 750
A13: 1180 | B13: Beneteau 373 | C13: 36'11" | D13: 2009 | E13: 10 | F13: 6 | G13: =IF(E13>8, "YES", "NO") -> YES | H13: 369 | I13: 725
A14: 1185 | B14: Hunter 36 | C14: 35'6" | D14: 2009 | E14: 10 | F14: 6 | G14: =IF(E14>8, "YES", "NO") -> YES | H14: 349 | I14: 550
A15: 1190 | B15: Beneteau 373 | C15: 36'11" | D15: 2010 | E15: 10 | F15: 6 | G15: =IF(E15>8, "YES", "NO") -> YES | H15: 369 | I15: 625
A16: 1200 | B16: Beneteau 373 | C16: 36'11" | D16: 2010 | E16: 10 | F16: 6 | G16: =IF(E16>8, "YES", "NO") -> YES | H16: 369 | I16: 625
... A19: 1230 | B19: Catalina 270 | C19: 28'4" | D19: 2012 | E19: 8 | F19: 6 | G19: =IF(E19>8, "YES", "NO") -> NO | H19: 439 | I19: 675

Sheet Project 3
A1: San Diego Sailing
A2: New Prices at 5% and 10% Increases
D3: Half-Day | F3: Full Day
A4: Boat ID | B4: Boat Type | C4: Length | D4: 0.05 | E4: 0.1 | F4: 0.05 | G4: 0.1
A5: 1010 | B5: Catalina 270 | C5: 28'4" | D5: =$D$4*'Project 2'!H5 -> 18.75 | E5: =$E$4*'Project 2'!H5 -> 37.5 | F5: =$F$4*'Project 2'!I5 -> 32.5 | G5: =$G$4*'Project 2'!I5 -> 65
A6: 1015 | B6: Catalina 270 | C6: 28'4" | D6: =$D$4*'Project 2'!H6 -> 21.25 | E6: =$E$4*'Project 2'!H6 -> 42.5 | F6: =$F$4*'Project 2'!I6 -> 36.25 | G6: =$G$4*'Project 2'!I6 -> 72.5
A7: 1146 | B7: Hunter 33 | C7: 33'6" | D7: =$D$4*'Project 2'!H7 -> 17.5 | E7: =$E$4*'Project 2'!H7 -> 35 | F7: =$F$4*'Project 2'!I7 -> 25 | G7: =$G$4*'Project 2'!I7 -> 50
A8: 1150 | B8: Capri 22 Mk II | C8: 24'8" | D8: =$D$4*'Project 2'!H8 -> 16.25 | E8: =$E$4*'Project 2'!H8 -> 32.5 | F8: =$F$4*'Project 2'!I8 -> 25 | G8: =$G$4*'Project 2'!I8 -> 50
A9: 1152 | B9: Capri 22 Mk II | C9: 24'8" | D9: =$D$4*'Project 2'!H9 -> 16.25 | E9: =$E$4*'Project 2'!H9 -> 32.5 | F9: =$F$4*'Project 2'!I9 -> 25 | G9: =$G$4*'Project 2'!I9 -> 50
A10: 1164 | B10: Capri 22 Mk II | C10: 24'8" | D10: =$D$4*'Project 2'!H10 -> 16.25 | E10: =$E$4*'Project 2'!H10 -> 32.5 | F10: =$F$4*'Project 2'!I10 -> 25 | G10: =$G$4*'Project 2'!I10 -> 50
A11: 1168 | B11: Hunter 33 | C11: 33'6" | D11: =$D$4*'Project 2'!H11 -> 21.25 | E11: =$E$4*'Project 2'!H11 -> 42.5 | F11: =$F$4*'Project 2'!I11 -> 36.25 | G11: =$G$4*'Project 2'!I11 -> 72.5
A12: 1175 | B12: Beneteau 40 | C12: 39'10" | D12: =$D$4*'Project 2'!H12 -> 24.45 | E12: =$E$4*'Project 2'!H12 -> 48.9 | F12: =$F$4*'Project 2'!I12 -> 37.5 | G12: =$G$4*'Project 2'!I12 -> 75
A13: 1180 | B13: Beneteau 373 | C13: 36'11" | D13: =$D$4*'Project 2'!H13 -> 18.45 | E13: =$E$4*'Project 2'!H13 -> 36.9 | F13: =$F$4*'Project 2'!I13 -> 36.25 | G13: =$G$4*'Project 2'!I13 -> 72.5
A14: 1185 | B14: Hunter 36 | C14: 35'6" | D14: =$D$4*'Project 2'!H14 -> 17.45 | E14: =$E$4*'Project 2'!H14 -> 34.9 | F14: =$F$4*'Project 2'!I14 -> 27.5 | G14: =$G$4*'Project 2'!I14 -> 55
A15: 1190 | B15: Beneteau 373 | C15: 36'11" | D15: =$D$4*'Project 2'!H15 -> 18.45 | E15: =$E$4*'Project 2'!H15 -> 36.9 | F15: =$F$4*'Project 2'!I15 -> 31.25 | G15: =$G$4*'Project 2'!I15 -> 62.5
A16: 1200 | B16: Beneteau 373 | C16: 36'11" | D16: =$D$4*'Project 2'!H16 -> 18.45 | E16: =$E$4*'Project 2'!H16 -> 36.9 | F16: =$F$4*'Project 2'!I16 -> 31.25 | G16: =$G$4*'Project 2'!I16 -> 62.5
... A19: 1230 | B19: Catalina 270 | C19: 28'4" | D19: =$D$4*'Project 2'!H19 -> 21.95 | E19: =$E$4*'Project 2'!H19 -> 43.9 | F19: =$F$4*'Project 2'!I19 -> 33.75 | G19: =$G$4*'Project 2'!I19 -> 67.5

Sheet Project 4
A1: San Diego Sailing Bookings
A2: Revenue per Passenger
A4: Date | B4: Boat ID | C4: Boat Type | D4: # of Passengers | E4: Total Fees | F4: Fees per Passenger
A5: 42465 | B5: 1010 | C5: Catalina 270 | D5: 4 | E5: 525 | F5: =E5/D5 -> 131.25
A6: 42468 | B6: 1015 | C6: Catalina 270 | D6: 6 | E6: 850 | F6: =E6/D6 -> 141.66667
A7: 42471 | B7: 1146 | C7: Hunter 33 | D7: 6 | E7: 500 | F7: =E7/D7 -> 83.333333
A8: 42474 | B8: 1150 | C8: Capri 22 Mk II | D8: 6 | E8: 525 | F8: =E8/D8 -> 87.5
A9: 42477 | B9: 1152 | C9: Capri 22 Mk II | D9: 4 | E9: 325 | F9: =E9/D9 -> 81.25
A10: 42480 | B10: 1164 | C10: Capri 22 Mk II | D10: 3 | E10: 475 | F10: =E10/D10 -> 158.33333
A11: 42483 | B11: 1168 | C11: Hunter 33 | D11: 6 | E11: 725 | F11: =E11/D11 -> 120.83333
A12: 42486 | B12: 1175 | C12: Beneteau 40 | D12: 10 | E12: 850 | F12: =E12/D12 -> 85
A13: 42489 | B13: 1180 | C13: Beneteau 373 | D13: 8 | E13: 350 | F13: =E13/D13 -> 43.75
A14: 42492 | B14: 1185 | C14: Hunter 36 | D14: 8 | E14: 650 | F14: =E14/D14 -> 81.25
A15: 42495 | B15: 1190 | C15: Beneteau 373 | D15: 10 | E15: 625 | F15: =E15/D15 -> 62.5
A16: 42498 | B16: 1200 | C16: Beneteau 373 | D16: 8 | E16: 725 | F16: =E16/D16 -> 90.625
... A19: 42507 | B19: 1230 | C19: Catalina 270 | D19: 6 | E19: 675 | F19: =E19/D19 -> 112.5
C25: Bookings by Type
D26: Count | E26: Total Fees
C27: Beneteau | D27: =COUNTIF(C5:C19, "*BEN*") -> 5 | E27: =SUMIF(C5:C19, "*ben*", E5:E19) -> 3400
C28: Capri 22 Mk II | D28: =COUNTIF(C5:C19, "*cap*") -> 3 | E28: =SUMIF(C5:C19, "*cap*", E5:E19) -> 1325
C29: Catalina 270 | D29: =COUNTIF(C5:C19,"*cat*") -> 3 | E29: =SUMIF(C5:C19, "*cat*", E5:E19) -> 2050
C30: Hunter | D30: =COUNTIF(C5:C19,"*Hun*") -> 4 | E30: =SUMIF(C5:C19, "*hun*", E5:E19) -> 2600

Sheet Project 5
A1: Classic Gardens and Landscapes (CGL)
A2: Revenue for Quarters 3 and 4
A4: Revenue Categories | B4: July | C4: August | D4: September | E4: October | F4: November | G4: December | H4: Total
A5: Lawn Maintenance | B5: 7660.125 | C5: 7741.125 | D5: 8123.8 | E5: 4500 | F5: 3250 | G5: 1225.75 | H5: =SUM(B5:G5) -> 32500.8
A6: Trees & Plants | B6: 11819.925 | C6: 10456.34 | D6: 12043.125 | E6: 11803.275 | F6: 11879.775 | G6: 12226.275 | H6: =SUM(B6:G6) -> 70228.715
A7: Patio and Furniture | B7: 15192.225 | C7: 13070.475 | D7: 12957.3 | E7: 13039.875 | F7: 15318.225 | G7: 16876.125 | H7: =SUM(B7:G7) -> 86454.225
A8: Fountains and Irrigation | B8: 4478.175 | C8: 4708.125 | D8: 4475.25 | E8: 5153.625 | F8: 5514.525 | G8: 7919.55 | H8: =SUM(B8:G8) -> 32249.25
A9: Landscape Design | B9: 1025 | C9: 1575.35 | D9: 1750 | E9: 1125.45 | F9: 725 | G9: 935.25 | H9: =SUM(B9:G9) -> 7136.05
A10: Total Revenue | B10: =SUM(B5:B9) -> 40175.45 | C10: =SUM(C5:C9) -> 37551.415 | D10: =SUM(D5:D9) -> 39349.475 | E10: =SUM(E5:E9) -> 35622.225 | F10: =SUM(F5:F9) -> 36687.525 | G10: =SUM(G5:G9) -> 39182.95 | H10: =SUM(H5:H9) -> 228569.04

Sheet Project 6
A1: Last Name | B1: First Name | C1: Employee Name | D1: Building | E1: Department | F1: Hire Date | G1: Years | H1: Benefits | I1: Salary | J1: Job Rating
A2: Page | B2: Lisa | C2: =_xlfn.TEXTJOIN(",",TRUE, Employee[[#This Row],[Last Name]], Employee[[#This Row],[First Name]]) -> Page, Lisa | D2: West | E2: ADC | F2: 37249 | G2: 15 | H2: DMR | I2: 60981 | J2: 1
A3: Taylor | B3: Hector | C3: =_xlfn.TEXTJOIN(",",TRUE, Employee[[#This Row],[Last Name]], Employee[[#This Row],[First Name]]) -> Taylor, Hector | D3: West | E3: ADC | F3: 41673 | G3: 3 | H3: DM | I3: 60915 | J3: 4
A4: Dawson | B4: Jonathan | C4: =_xlfn.TEXTJOIN(",",TRUE, Employee[[#This Row],[Last Name]], Employee[[#This Row],[First Name]]) -> Dawson, Jonathan | D4: West | E4: ADC | F4: 40225 | G4: 7 | I4: 97071 | J4: 5
A5: Duran | B5: Brian | C5: =_xlfn.TEXTJOIN(",",TRUE, Employee[[#This Row],[Last Name]], Employee[[#This Row],[First Name]]) -> Duran, Brian | D5: Taft | E5: ADC | F5: 42229 | G5: 2 | I5: 115421 | J5: 3
A6: Weber | B6: Larry | C6: =_xlfn.TEXTJOIN(",",TRUE, Employee[[#This Row],[Last Name]], Employee[[#This Row],[First Name]]) -> Weber, Larry | D6: Watson | E6: ADC | F6: 40525 | G6: 6 | H6: M | I6: 115547 | J6: 4
A7: Pratt | B7: Erik | C7: =_xlfn.TEXTJOIN(",",TRUE, Employee[[#This Row],[Last Name]], Employee[[#This Row],[First Name]]) -> Pratt, Erik | D7: North | E7: Training | F7: 39829 | G7: 8 | H7: DMR | I7: 69212 | J7: 2
A8: O'Connor | B8: Kent | C8: =_xlfn.TEXTJOIN(",",TRUE, Employee[[#This Row],[Last Name]], Employee[[#This Row],[First Name]]) -> O'Connor, Kent | D8: Taft | E8: Training | F8: 37295 | G8: 15 | H8: DMR | I8: 120198 | J8: 1
A9: Spencer | B9: Boyd | C9: =_xlfn.TEXTJOIN(",",TRUE, Employee[[#This Row],[Last Name]], Employee[[#This Row],[First Name]]) -> Spencer, Boyd | D9: Main | E9: Training | F9: 40267 | G9: 7 | I9: 107635 | J9: 5
A10: Wiggins | B10: Frank | C10: =_xlfn.TEXTJOIN(",",TRUE, Employee[[#This Row],[Last Name]], Employee[[#This Row],[First Name]]) -> Wiggins, Frank | D10: North | E10: Training | F10: 37338 | G10: 15 | H10: DMR | I10: 113020 | J10: 1
A11: Tanner | B11: Timothy | C11: =_xlfn.TEXTJOIN(",",TRUE, Employee[[#This Row],[Last Name]], Employee[[#This Row],[First Name]]) -> Tanner, Timothy | D11: Taft | E11: Training | F11: 38482 | G11: 12 | H11: DMR | I11: 82341 | J11: 4
A12: Strickland | B12: Rajean | C12: =_xlfn.TEXTJOIN(",",TRUE, Employee[[#This Row],[Last Name]], Employee[[#This Row],[First Name]]) -> Strickland, Rajean | D12: Main | E12: Training | F12: 38860 | G12: 11 | H12: D | I12: 98598 | J12: 3
A13: Chase | B13: Troy | C13: =_xlfn.TEXTJOIN(",",TRUE, Employee[[#This Row],[Last Name]], Employee[[#This Row],[First Name]]) -> Chase, Troy | D13: Main | E13: Training | F13: 39220 | G13: 10 | H13: DMR | I13: 46350 | J13: 4
A14: Brewer | B14: Kent | C14: =_xlfn.TEXTJOIN(",",TRUE, Employee[[#This Row],[Last Name]], Employee[[#This Row],[First Name]]) -> Brewer, Kent | D14: Main | E14: Training | F14: 41857 | G14: 3 | H14: DM | I14: 61076 | J14: 1
A15: Wilkins | B15: Jesse | C15: =_xlfn.TEXTJOIN(",",TRUE, Employee[[#This Row],[Last Name]], Employee[[#This Row],[First Name]]) -> Wilkins, Jesse | D15: North | E15: Training | F15: 42214 | G15: 2 | H15: DMR | I15: 107968 | J15: 5
A16: White | B16: Daniel | C16: =_xlfn.TEXTJOIN(",",TRUE, Employee[[#This Row],[Last Name]], Employee[[#This Row],[First Name]]) -> White, Daniel | D16: Watson | E16: Training | F16: 37842 | G16: 14 | H16: D | I16: 102146 | J16: 4
A17: Holland | B17: Donald | C17: =_xlfn.TEXTJOIN(",",TRUE, Employee[[#This Row],[Last Name]], Employee[[#This Row],[First Name]]) -> Holland, Donald | D17: South | E17: Training | F17: 41865 | G17: 3 | H17: DMR | I17: 46009 | J17: 3
A18: Rowe | B18: Ken | C18: =_xlfn.TEXTJOIN(",",TRUE, Employee[[#This Row],[Last Name]], Employee[[#This Row],[First Name]]) -> Rowe, Ken | D18: West | E18: Training | F18: 37855 | G18: 14 | I18: 53399 | J18: 3
A19: Burton | B19: Cam | C19: =_xlfn.TEXTJOIN(",",TRUE, Employee[[#This Row],[Last Name]], Employee[[#This Row],[First Name]]) -> Burton, Cam | D19: West | E19: Training | F19: 40782 | G19: 6 | H19: D | I19: 45419 | J19: 5
A20: Phillips | B20: Liesl | C20: =_xlfn.TEXTJOIN(",",TRUE, Employee[[#This Row],[Last Name]], Employee[[#This Row],[First Name]]) -> Phillips, Liesl | D20: South | E20: Training | F20: 40107 | G20: 7 | H20: R | I20: 69038 | J20: 2
A21: Gallagher | B21: Johnson | C21: =_xlfn.TEXTJOIN(",",TRUE, Employee[[#This Row],[Last Name]], Employee[[#This Row],[First Name]]) -> Gallagher, Johnson | D21: West | E21: Training | F21: 41204 | G21: 4 | I21: 46163 | J21: 4
A22: Wolf | B22: Debbie | C22: =_xlfn.TEXTJOIN(",",TRUE, Employee[[#This Row],[Last Name]], Employee[[#This Row],[First Name]]) -> Wolf, Debbie | D22: Taft | E22: Training | F22: 37221 | G22: 15 | H22: R | I22: 70990 | J22: 5
A23: Todd | B23: Steven | C23: =_xlfn.TEXTJOIN(",",TRUE, Employee[[#This Row],[Last Name]], Employee[[#This Row],[First Name]]) -> Todd, Steven | D23: Watson | E23: Training | F23: 40147 | G23: 7 | H23: M | I23: 45315 | J23: 3
A24: McKenzie | B24: Michelle | C24: =_xlfn.TEXTJOIN(",",TRUE, Employee[[#This Row],[Last Name]], Employee[[#This Row],[First Name]]) -> McKenzie, Michelle | D24: Main | E24: Environmental Compliance | F24: 39824 | G24: 8 | H24: R | I24: 102687 | J24: 2
A25: Thornton | B25: Charles | C25: =_xlfn.TEXTJOIN(",",TRUE, Employee[[#This Row],[Last Name]], Employee[[#This Row],[First Name]]) -> Thornton, Charles | D25: West | E25: Environmental Compliance | F25: 37971 | G25: 13 | H25: R | I25: 121213 | J25: 3
A26: Dunn | B26: Matthew | C26: =_xlfn.TEXTJOIN(",",TRUE, Employee[[#This Row],[Last Name]], Employee[[#This Row],[First Name]]) -> Dunn, Matthew | D26: North | E26: Environmental Compliance | F26: 37292 | G26: 15 | H26: D | I26: 74666 | J26: 1
A27: Potter | B27: Dawn | C27: =_xlfn.TEXTJOIN(",",TRUE, Employee[[#This Row],[Last Name]], Employee[[#This Row],[First Name]]) -> Potter, Dawn | D27: Taft | E27: Environmental Compliance | F27: 39129 | G27: 10 | H27: DMR | I27: 90032 | J27: 1
A28: Carroll | B28: Lesa | C28: =_xlfn.TEXTJOIN(",",TRUE, Employee[[#This Row],[Last Name]], Employee[[#This Row],[First Name]]) -> Carroll, Lesa | D28: West | E28: Environmental Compliance | F28: 37697 | G28: 14 | H28: M | I28: 43469 | J28: 1
A29: Fleming | B29: Irv | C29: =_xlfn.TEXTJOIN(",",TRUE, Employee[[#This Row],[Last Name]], Employee[[#This Row],[First Name]]) -> Fleming, Irv | D29: West | E29: Environmental Compliance | F29: 39929 | G29: 8 | H29: DMR | I29: 68870 | J29: 1
A30: Nguyen | B30: Dennis | C30: =_xlfn.TEXTJOIN(",",TRUE, Employee[[#This Row],[Last Name]], Employee[[#This Row],[First Name]]) -> Nguyen, Dennis | D30: Main | E30: Environmental Compliance | F30: 40039 | G30: 8 | I30: 113141 | J30: 4
A31: Blair | B31: Sperry | C31: =_xlfn.TEXTJOIN(",",TRUE, Employee[[#This Row],[Last Name]], Employee[[#This Row],[First Name]]) -> Blair, Sperry | D31: West | E31: Environmental Compliance | F31: 41184 | G31: 5 | H31: DM | I31: 104719 | J31: 3
A32: Wyatt | B32: Kelly | C32: =_xlfn.TEXTJOIN(",",TRUE, Employee[[#This Row],[Last Name]], Employee[[#This Row],[First Name]]) -> Wyatt, Kelly | D32: West | E32: Environmental Compliance | F32: 41934 | G32: 2 | H32: DM | I32: 61443 | J32: 2
A33: Walton | B33: Benjamin | C33: =_xlfn.TEXTJOIN(",",TRUE, Employee[[#This Row],[Last Name]], Employee[[#This Row],[First Name]]) -> Walton, Benjamin | D33: North | E33: Environmental Compliance | F33: 40492 | G33: 6 | H33: DMR | I33: 115351 | J33: 1
A34: Beck | B34: Craig | C34: =_xlfn.TEXTJOIN(",",TRUE, Employee[[#This Row],[Last Name]], Employee[[#This Row],[First Name]]) -> Beck, Craig | D34: North | E34: Environmental Compliance | F34: 42096 | G34: 2 | H34: DMR | I34: 71321 | J34: 3
A35: Phelps | B35: Gretchen | C35: =_xlfn.TEXTJOIN(",",TRUE, Employee[[#This Row],[Last Name]], Employee[[#This Row],[First Name]]) -> Phelps, Gretchen | D35: South | E35: Environmental Compliance | F35: 41586 | G35: 3 | I35: 124798 | J35: 2
A36: Bond | B36: John | C36: =_xlfn.TEXTJOIN(",",TRUE, Employee[[#This Row],[Last Name]], Employee[[#This Row],[First Name]]) -> Bond, John | D36: North | E36: Environmental Compliance | F36: 40495 | G36: 6 | H36: M | I36: 96545 | J36: 3
A37: Chang | B37: Gabriel | C37: =_xlfn.TEXTJOIN(",",TRUE, Employee[[#This Row],[Last Name]], Employee[[#This Row],[First Name]]) -> Chang, Gabriel | D37: Main | E37: Environmental Compliance | F37: 41230 | G37: 4 | H37: R | I37: 98833 | J37: 1
A38: Bullock | B38: Greg | C38: =_xlfn.TEXTJOIN(",",TRUE, Employee[[#This Row],[Last Name]], Employee[[#This Row],[First Name]]) -> Bullock, Greg | D38: North | E38: Facilities/Engineering | F38: 42003 | G38: 2 | I38: 124698 | J38: 3
A39: Wheeler | B39: Meegan | C39: =_xlfn.TEXTJOIN(",",TRUE, Employee[[#This Row],[Last Name]], Employee[[#This Row],[First Name]]) -> Wheeler, Meegan | D39: West | E39: Facilities/Engineering | F39: 40172 | G39: 7 | I39: 106453 | J39: 4
A40: Cunningham | B40: Denise | C40: =_xlfn.TEXTJOIN(",",TRUE, Employee[[#This Row],[Last Name]], Employee[[#This Row],[First Name]]) -> Cunningham, Denise | D40: Main | E40: Facilities/Engineering | F40: 41278 | G40: 4 | H40: M | I40: 88169 | J40: 5
...

Sheet Project 7
A1: The Roux Academy of Art
A5: 2017 Faculty Members
A6: Position | B6: Staff Member | C6: Department | D6: Left | E6: Right | F6: Length | G6: Password
A7: Admin Assistant | B7: Nell Gomez | C7: Admin | D7: =LEFT(B7, 3) -> Nel | E7: =RIGHT(A7, 5) -> stant | F7: =LEN(B7) -> 10 | G7: =_xlfn.CONCAT(D7, E7, F7) -> Nelstant10
A8: Asst. Headmaster | B8: Roland Hale | C8: Admin | D8: =LEFT(B8, 3) -> Rol | E8: =RIGHT(A8, 5) -> aster | F8: =LEN(B8) -> 11 | G8: =_xlfn.CONCAT(D8, E8, F8) -> Rolaster11
A9: Counselor | B9: Bob Steele | C9: Admin | D9: =LEFT(B9, 3) -> Bob | E9: =RIGHT(A9, 5) -> selor | F9: =LEN(B9) -> 10 | G9: =_xlfn.CONCAT(D9, E9, F9) -> Bobselor10
A10: Counselor | B10: Lauryn Drake | C10: Admin | D10: =LEFT(B10, 3) -> Lau | E10: =RIGHT(A10, 5) -> selor | F10: =LEN(B10) -> 12 | G10: =_xlfn.CONCAT(D10, E10, F10) -> Lauselor12
A11: Counselor | B11: Trinidad Faulkner | C11: Admin | D11: =LEFT(B11, 3) -> Tri | E11: =RIGHT(A11, 5) -> selor | F11: =LEN(B11) -> 17 | G11: =_xlfn.CONCAT(D11, E11, F11) -> Triselor17
A12: Counselor | B12: Sixta Jarvis | C12: Admin | D12: =LEFT(B12, 3) -> Six | E12: =RIGHT(A12, 5) -> selor | F12: =LEN(B12) -> 12 | G12: =_xlfn.CONCAT(D12, E12, F12) -> Sixselor12
A13: Counselor | B13: Shayna Cantrell | C13: Admin | D13: =LEFT(B13, 3) -> Sha | E13: =RIGHT(A13, 5) -> selor | F13: =LEN(B13) -> 15 | G13: =_xlfn.CONCAT(D13, E13, F13) -> Shaselor15
A14: Headmaster | B14: Deneen Richards | C14: Admin | D14: =LEFT(B14, 3) -> Den | E14: =RIGHT(A14, 5) -> aster | F14: =LEN(B14) -> 15 | G14: =_xlfn.CONCAT(D14, E14, F14) -> Denaster15
A15: Janitorial | B15: Rubye Donaldson | C15: Admin | D15: =LEFT(B15, 3) -> Rub | E15: =RIGHT(A15, 5) -> orial | F15: =LEN(B15) -> 15 | G15: =_xlfn.CONCAT(D15, E15, F15) -> Ruborial15
A16: Janitorial | B16: Fannie Buckner | C16: Admin | D16: =LEFT(B16, 3) -> Fan | E16: =RIGHT(A16, 5) -> orial | F16: =LEN(B16) -> 14 | G16: =_xlfn.CONCAT(D16, E16, F16) -> Fanorial14
A17: Nurse | B17: Luann Hull | C17: Admin | D17: =LEFT(B17, 3) -> Lua | E17: =RIGHT(A17, 5) -> Nurse | F17: =LEN(B17) -> 10 | G17: =_xlfn.CONCAT(D17, E17, F17) -> LuaNurse10
A18: Secretary | B18: Dorie Salinas | C18: Admin | D18: =LEFT(B18, 3) -> Dor | E18: =RIGHT(A18, 5) -> etary | F18: =LEN(B18) -> 13 | G18: =_xlfn.CONCAT(D18, E18, F18) -> Doretary13
... A35: Photography | B35: Bee Anthony | C35: Teacher | D35: =LEFT(B35, 3) -> Bee | E35: =RIGHT(A35, 5) -> raphy | F35: =LEN(B35) -> 11 | G35: =_xlfn.CONCAT(D35, E35, F35) -> Beeraphy11
